<?xml version="1.0" ?>
<!-- =================================================================================== -->
<!-- |    This document was autogenerated by xacro from wam_4dof.urdf.xacro            | -->
<!-- |    EDITING THIS FILE BY HAND IS NOT RECOMMENDED                                 | -->
<!-- =================================================================================== -->
<robot name="wam" xmlns:controller="http://playerstage.sourceforge.net/gazebo/xmlschema/#controller" xmlns:interface="http://playerstage.sourceforge.net/gazebo/xmlschema/#interface" xmlns:sensor="http://playerstage.sourceforge.net/gazebo/xmlschema/#sensor" xmlns:xacro="http://www.ros.org/wiki/xacro">
  <!-- LINKS   -->
  <link name="world"/>
  <link name="wam_base">
    <inertial>
      <mass value="9.97059584"/>
      <origin rpy="0 0 0" xyz="0.0 0.0 0.0"/>
      <inertia ixx="1.0" ixy="0.0" ixz="0.0" iyy="1.0" iyz="0.0" izz="1.0"/>
    </inertial>
    <visual>
      <origin rpy="0 0 0" xyz="0.0 0.0 0.0"/>
      <geometry name="wam_base_visual">
        <mesh filename="package://wam_description/meshes/wam_base.mesh" scale="1.0 1.0 1.0"/>
      </geometry>
      <material name="White">
        <color rgba="0.0 0.0 0.0 1.0"/>
      </material>
    </visual>
    <collision>
      <origin rpy="0 0 0" xyz="0.0 0.0 0.0"/>
      <geometry name="wam_base_collision">
        <mesh filename="package://wam_description/meshes/wam_base.mesh" scale="1.0 1.0 1.0"/>
      </geometry>
      <contact_coefficients kd="1.0" kp="1000.0" mu="0"/>
    </collision>
  </link>
  <gazebo reference="wam_base">
    <material>Gazebo/White</material>
    <selfCollide>true</selfCollide>
  </gazebo>
  <joint name="wam_base_joint" type="fixed">
    <parent link="world"/>
    <child link="wam_base"/>
    <origin rpy="0 0 0" xyz="0.0 0.0 0.0"/>
  </joint>
  <link name="wam_j1">
    <inertial>
      <mass value="10.76768767"/>
      <origin rpy="0 0 0" xyz="0.0 0.0 0.0"/>
      <inertia ixx="1.0" ixy="0.0" ixz="0.0" iyy="1.0" iyz="0.0" izz="1.0"/>
    </inertial>
    <visual>
      <origin rpy="0 0 0" xyz="0.0 0.0 0.0"/>
      <geometry name="wam_j1_visual">
        <mesh filename="package://wam_description/meshes/link_j1.mesh" scale="1.0 1.0 1.0"/>
      </geometry>
      <material name="Grey">
        <color rgba="0.75 0.75 0.75 1.0"/>
      </material>
    </visual>
    <collision>
      <origin rpy="0 0 0" xyz="0.0 0.0 0.0"/>
      <geometry name="wam_j1_collision">
        <mesh filename="package://wam_description/meshes/link_j1.mesh" scale="1.0 1.0 1.0"/>
      </geometry>
      <contact_coefficients kd="1.0" kp="1000.0" mu="0"/>
    </collision>
  </link>
  <gazebo reference="wam_j1">
    <material>Gazebo/White</material>
    <selfCollide>true</selfCollide>
  </gazebo>
  <joint name="wam_j1_joint" type="revolute">
    <parent link="wam_base"/>
    <child link="wam_j1"/>
    <origin rpy="0 0 0" xyz="0.22 0.14 0.346"/>
    <axis xyz="0 0 1"/>
    <limit effort="30" lower="-2.6" upper="2.6" velocity="2.0"/>
    <dynamics damping="100"/>
  </joint>
  <transmission name="wam_j1_transmission" type="pr2_mechanism_model/SimpleTransmission">
    <actuator name="j1_motor"/>
    <joint name="wam_j1_joint"/>
    <mechanicalReduction>1</mechanicalReduction>
    <motorTorqueConstant>1</motorTorqueConstant>
  </transmission>
  <link name="wam_j2">
    <inertial>
      <mass value="3.87493756"/>
      <origin rpy="0 0 0" xyz="0 0 0"/>
      <inertia ixx="1.0" ixy="0.0" ixz="0.0" iyy="0.1" iyz="0.0" izz="0.1"/>
    </inertial>
    <visual>
      <origin rpy="0 0 0" xyz="0.0 0.0 0.0"/>
      <geometry name="wam_j2_visual">
        <mesh filename="package://wam_description/meshes/link_j2.mesh" scale="1.0 1.0 1.0"/>
      </geometry>
      <material name="Grey">
        <color rgba="0.75 0.75 0.75 1.0"/>
      </material>
    </visual>
    <collision>
      <origin rpy="0 0 0" xyz="0.0 0.0 0.0"/>
      <geometry name="wam_j2_collision">
        <mesh filename="package://wam_description/meshes/link_j2.mesh" scale="1.0 1.0 1.0"/>
      </geometry>
      <contact_coefficients kd="1.0" kp="1000.0" mu="0"/>
    </collision>
  </link>
  <gazebo reference="wam_j2">
    <material>Gazebo/Grey</material>
    <selfCollide>true</selfCollide>
  </gazebo>
  <joint name="wam_j2_joint" type="revolute">
    <parent link="wam_j1"/>
    <child link="wam_j2"/>
    <origin rpy="0 0 0" xyz="0.0 0.0 0.0"/>
    <axis xyz="0 1 0"/>
    <limit effort="30" lower="-2.0" upper="2.0" velocity="2.0"/>
    <dynamics damping="100"/>
  </joint>
  <transmission name="wam_j2_transmission" type="pr2_mechanism_model/SimpleTransmission">
    <actuator name="j2_motor"/>
    <joint name="wam_j2_joint"/>
    <mechanicalReduction>1</mechanicalReduction>
    <motorTorqueConstant>1</motorTorqueConstant>
  </transmission>
  <link name="wam_j3">
    <inertial>
      <mass value="1.80228141"/>
      <!-- Weird origin -->
      <origin rpy="0 0 0" xyz="0 0 0.225"/>
      <inertia ixx="1.0" ixy="0.0" ixz="0.0" iyy="0.1" iyz="0.0" izz="0.1"/>
    </inertial>
    <visual>
      <origin rpy="0 0 0" xyz="0.0 0.0 0.0"/>
      <geometry name="wam_j3_visual">
        <mesh filename="package://wam_description/meshes/link_j3.mesh" scale="1.0 1.0 1.0"/>
      </geometry>
      <material name="Grey">
        <color rgba="0.75 0.75 0.75 1.0"/>
      </material>
    </visual>
    <collision>
      <origin rpy="0 0 0" xyz="0.0 0.0 0.0"/>
      <geometry name="wam_j3_collision">
        <mesh filename="package://wam_description/meshes/link_j3.mesh" scale="1.0 1.0 1.0"/>
      </geometry>
      <contact_coefficients kd="1.0" kp="1000.0" mu="0"/>
    </collision>
  </link>
  <gazebo reference="wam_j3">
    <material>Gazebo/Grey</material>
    <selfCollide>false</selfCollide>
  </gazebo>
  <joint name="wam_j3_joint" type="revolute">
    <parent link="wam_j2"/>
    <child link="wam_j3"/>
    <origin rpy="0 0 0" xyz="0.0 0.0 0.0"/>
    <axis xyz="0 0 1"/>
    <limit effort="30" lower="-2.8" upper="2.8" velocity="2.0"/>
    <dynamics damping="100"/>
  </joint>
  <transmission name="wam_j3_transmission" type="pr2_mechanism_model/SimpleTransmission">
    <actuator name="j3_motor"/>
    <joint name="wam_j3_joint"/>
    <mechanicalReduction>1</mechanicalReduction>
    <motorTorqueConstant>1</motorTorqueConstant>
  </transmission>
  <link name="wam_j4">
    <inertial>
      <mass value="1.06513649"/>
      <!-- another strange origin -->
      <origin rpy="0 0 0" xyz="-0.045 -0.15 0"/>
      <inertia ixx="1.0" ixy="0.0" ixz="0.0" iyy="0.1" iyz="0.0" izz="0.1"/>
    </inertial>
    <visual>
      <origin rpy="0 0 0" xyz="0.0 0.0 0.0"/>
      <geometry name="wam_j4_visual">
        <mesh filename="package://wam_description/meshes/link_j4.mesh" scale="1.0 1.0 1.0"/>
      </geometry>
      <material name="Grey">
        <color rgba="0.75 0.75 0.75 1.0"/>
      </material>
    </visual>
    <collision>
      <origin rpy="0 0 0" xyz="0.0 0.0 0.0"/>
      <geometry name="wam_j4_collision">
        <mesh filename="package://wam_description/meshes/link_j4.mesh" scale="1.0 1.0 1.0"/>
      </geometry>
      <contact_coefficients kd="1.0" kp="1000.0" mu="0"/>
    </collision>
  </link>
  <gazebo reference="wam_j4">
    <material>Gazebo/Grey</material>
    <selfCollide>true</selfCollide>
  </gazebo>
  <joint name="wam_j4_joint" type="revolute">
    <parent link="wam_j3"/>
    <child link="wam_j4"/>
    <origin rpy="-1.57079632679 0 0" xyz="0.045 0.0 0.55"/>
    <axis xyz="0 0 1"/>
    <limit effort="35" lower="-0.9" upper="2.8" velocity="2.0"/>
    <dynamics damping="100"/>
  </joint>
  <transmission name="wam_j4_transmission" type="pr2_mechanism_model/SimpleTransmission">
    <actuator name="j4_motor"/>
    <joint name="wam_j4_joint"/>
    <mechanicalReduction>1</mechanicalReduction>
    <motorTorqueConstant>1</motorTorqueConstant>
  </transmission>
  <link name="wam_tool_plate">
    <inertial>
      <mass value="0.0001"/>
      <inertia ixx="1.0" ixy="0.0" ixz="0.0" iyy="1.0" iyz="0.0" izz="1.0"/>
    </inertial>
    <visual>
      <origin rpy="0 0 0" xyz="0.0 0.0 0.0"/>
      <geometry name="wam_tool_plate_visual">
        <box size="0.001 0.001 0.001"/>
      </geometry>
      <material name="Grey">
        <color rgba="0.75 0.75 0.75 1.0"/>
      </material>
    </visual>
    <collision>
      <origin rpy="0 0 0" xyz="0.0 0.0 0.0"/>
      <geometry name="wam_base_collision">
        <box size="0.001 0.001 0.001"/>
      </geometry>
      <contact_coefficients kd="1.0" kp="1000.0" mu="0"/>
    </collision>
  </link>
  <gazebo reference="wam_tool_plate">
    <material>Gazebo/Grey</material>
    <selfCollide>true</selfCollide>
  </gazebo>
  <joint name="wam_tool_plate_joint" type="fixed">
    <parent link="wam_j4"/>
    <child link="wam_tool_plate"/>
    <origin rpy="1.57079632679 0 0" xyz="-0.045 -0.3 0.0"/>
  </joint>
</robot>

