<?xml version="1.0"?>

<robot xmlns:xacro="http://www.ros.org/wiki/xacro">
<property name="M_PI" value="3.1415926535897931" />
  <xacro:macro name="wam_j3" params="parent">

    <link name="wam_j3">
        <inertial>
            <mass value="1.80228141" />
            <!-- Weird origin -->
            <origin xyz="0 0 0.225" rpy="0 0 0" />
            <inertia  ixx="1.0" ixy="0.0"  ixz="0.0"  iyy="0.1"  iyz="0.0"  izz="0.1" />
        </inertial>
        <visual>
            <origin xyz="0.0 0.0 0.0" rpy="0 0 0" />
            <geometry name="wam_j3_visual">
                <mesh filename="package://wam_description/meshes/link_j3.mesh" scale="1.0 1.0 1.0" />
            </geometry>
            <material name="Grey" >
                <color rgba="0.75 0.75 0.75 1.0"/>
            </material>
        </visual>
        <collision>
            <origin xyz="0.0 0.0 0.0" rpy="0 0 0"/>
            <geometry name="wam_j3_collision">
                <mesh filename="package://wam_description/meshes/link_j3.mesh" scale="1.0 1.0 1.0" />
            </geometry>
            <contact_coefficients kd="1.0" kp="1000.0" mu="0"/>
        </collision>
    </link>
    <gazebo reference="wam_j3">
        <material>Gazebo/Grey</material>
        <selfCollide>false</selfCollide>
    </gazebo>

    <joint name="wam_j3_joint" type="revolute">
        <parent link="${parent}"/>
        <child link="wam_j3"/>
        <origin xyz="0.0 0.0 0.0" rpy="0 0 0" />
        <axis xyz="0 0 1" />
        <limit lower="-2.8" upper="2.8" effort="30" velocity="2.0"/>
        <dynamics damping="100"/>
    </joint>

    <transmission type="pr2_mechanism_model/SimpleTransmission" name="wam_j3_transmission">
      <actuator name="j3_motor" />
      <joint name="wam_j3_joint" />
      <mechanicalReduction>1</mechanicalReduction>
      <motorTorqueConstant>1</motorTorqueConstant>
    </transmission>

  </xacro:macro>

</robot>
